Workbook

Sheet README - Ground Truth
B2: Three Sisters Kitchen — MENTOR Demo Dataset
B3: Facilitator notes: what's embedded in this workbook, and where. For your reference only — not part of the live demo.
B5: Company | C5: Three Sisters Kitchen — 3-site independent hospitality chain (Camden, Shoreditch, Greenwich, London). Casual dining + delivery + events. No ERP, runs entirely on Excel.
B6: Period covered | C6: May, June, July 2026 — three full months, so month-over-month variance is real, not a single snapshot.
B8: HARD CASE 1 — Vendor renamed mid-year | C8: 'Fresh Fields Produce Ltd' (May invoices) becomes 'Fresh Fields Wholesale Ltd' from June onward — same vendor, rebranded. See 'Raw - Supplier Invoices'. MENTOR should recognise these as the same vendor via pattern memory, not two different suppliers.
B9: HARD CASE 2 — Duplicate invoice | C9: CleanPro Services, Camden, July: invoice INV-CP-507 and INV-CP-0714B are the same charge (£310 net) entered twice. Bank statement shows only ONE matching payment — the giveaway. See 'Raw - Supplier Invoices' (rows for CleanPro, July, Camden) and 'Raw - Bank Statement'.
B10: HARD CASE 3 — VAT rate misapplied | C10: Metro Drinks Wholesale, Camden, June invoice: alcohol should be standard-rated (20%) but was entered at 0% (the zero-rating that applies to most food, wrongly applied here). A genuine compliance catch, not just a maths error.
B11: HARD CASE 4 — Missing invoice | C11: Greenwich Linen Co: bank statement shows a payment in June (£410), but there is no matching invoice in 'Raw - Supplier Invoices' for June (invoice exists for May and July only). Real-world missing documentation, not a data error MENTOR can 'fix' — it should flag and ask for the invoice.
B12: HARD CASE 5 — Genuine judgment ambiguity: price rise vs wastage | C12: Coastal Seafood Direct unit prices rise ~18% from July 1 (one invoice note references a supplier price-increase letter). At the same time, July food cost % rises across all three sites, which could equally reflect wastage from a July heatwave (mentioned informally, not documented anywhere). This is deliberately NOT resolved in the data — the correct MENTOR behaviour is to surface both possibilities and ask the user to confirm, not silently pick one.
B13: HARD CASE 6 — Commission rate change buried in net payouts | C13: Deliveroo commission rises from 28% (May) to 30% (June onward). Payouts on the bank statement are net of commission, so a naive read makes delivery revenue look like it's falling in June/July when gross sales are actually flat or up. See 'Assumptions' table on the P&L (Answer Key) sheet.
B14: HARD CASE 7 — Inconsistent date entry | C14: One Deliveroo payout line (Camden, July) was entered with the date as text '14.07.2026' instead of a proper date — a realistic messy-data artefact. See 'Raw - Bank Statement', column 'Date (as entered)' vs 'Date (parsed)'.
B15: HARD CASE 8 — Tronc / tips judgment | C15: Payroll sheet includes Tronc (tips redistributed to staff) as a line, but it is deliberately EXCLUDED from Payroll Cost in the P&L, since it passes straight through to staff and is not a real cost to the business. Worth narrating to your friends as an example of a judgment call MENTOR should get right, not just sum every column blindly.
B16: Scope caveat | C16: For manageability, the Raw Data only models the recurring vendor relationships that matter for the demo (produce, seafood, bakery, drinks, cleaning/linen, maintenance, marketing) rather than a full purchase ledger. COGS and Opex will read a little lean against real hospitality benchmarks (typically 28-32% food cost) — worth saying so upfront if your finance friends ask, rather than presenting it as a complete ledger.
B18: How to run the demo | C18: 1) Show 'Raw - Supplier Invoices' and 'Raw - Bank Statement' first — let your friends see how messy real input looks. 2) Open 'Monthly P&L (Demo - Start Here)' — this is blank on purpose. Build it live with MENTOR watching, so they see it notice the header, suggest totals, then flag the hard cases as you go. 3) Reveal 'Monthly P&L (Answer Key)' and 'Variance Analysis' afterwards to show the finished, correct version, including the two cases (5 and 6) that stay flagged rather than silently resolved.

Sheet Raw - Supplier Invoices
A1: Raw Data — Supplier Invoices (May–Jul 2026, unstructured, as received)
A3: Invoice ID | B3: Site | C3: Vendor (as entered) | D3: Invoice Date | E3: Category | F3: Net Amount (£) | G3: VAT Rate | H3: VAT Amount (£) | I3: Gross Amount (£) | J3: Payment Status | K3: Notes
A4: INV-FF-101 | B4: Camden | C4: Fresh Fields Produce Ltd | D4: 46146 | E4: Food | F4: 1350 | G4: 0 | H4: =F4*G4 -> 0 | I4: =F4*(1+G4) -> 1350 | J4: Paid
A5: INV-CS-201 | B5: Camden | C5: Coastal Seafood Direct | D5: 46148 | E5: Food | F5: 1750 | G5: 0 | H5: =F5*G5 -> 0 | I5: =F5*(1+G5) -> 1750 | J5: Paid
A6: INV-MD-301 | B6: Camden | C6: Metro Drinks Wholesale | D6: 46152 | E6: Beverage | F6: 900 | G6: 0.2 | H6: =F6*G6 -> 180 | I6: =F6*(1+G6) -> 1080 | J6: Paid
A7: INV-GC-401 | B7: Camden | C7: Golden Crust Bakery Co | D7: 46150 | E7: Food | F7: 390 | G7: 0 | H7: =F7*G7 -> 0 | I7: =F7*(1+G7) -> 390 | J7: Paid
A8: INV-CP-501 | B8: Camden | C8: CleanPro Services | D8: 46154 | E8: Cleaning/Supplies | F8: 310 | G8: 0.2 | H8: =F8*G8 -> 62 | I8: =F8*(1+G8) -> 372 | J8: Paid
A9: INV-FF-102 | B9: Shoreditch | C9: Fresh Fields Produce Ltd | D9: 46146 | E9: Food | F9: 1260 | G9: 0 | H9: =F9*G9 -> 0 | I9: =F9*(1+G9) -> 1260 | J9: Paid
A10: INV-CS-202 | B10: Shoreditch | C10: Coastal Seafood Direct | D10: 46148 | E10: Food | F10: 1595 | G10: 0 | H10: =F10*G10 -> 0 | I10: =F10*(1+G10) -> 1595 | J10: Paid
A11: INV-MD-302 | B11: Shoreditch | C11: Metro Drinks Wholesale | D11: 46152 | E11: Beverage | F11: 840 | G11: 0.2 | H11: =F11*G11 -> 168 | I11: =F11*(1+G11) -> 1008 | J11: Paid
A12: INV-GC-402 | B12: Shoreditch | C12: Golden Crust Bakery Co | D12: 46150 | E12: Food | F12: 360 | G12: 0 | H12: =F12*G12 -> 0 | I12: =F12*(1+G12) -> 360 | J12: Paid
A13: INV-CP-502 | B13: Shoreditch | C13: CleanPro Services | D13: 46154 | E13: Cleaning/Supplies | F13: 295 | G13: 0.2 | H13: =F13*G13 -> 59 | I13: =F13*(1+G13) -> 354 | J13: Paid
A14: INV-FF-103 | B14: Greenwich | C14: Fresh Fields Produce Ltd | D14: 46146 | E14: Food | F14: 1175 | G14: 0 | H14: =F14*G14 -> 0 | I14: =F14*(1+G14) -> 1175 | J14: Paid
A15: INV-CS-203 | B15: Greenwich | C15: Coastal Seafood Direct | D15: 46148 | E15: Food | F15: 1550 | G15: 0 | H15: =F15*G15 -> 0 | I15: =F15*(1+G15) -> 1550 | J15: Paid
... A18: INV-CP-503 | B18: Greenwich | C18: CleanPro Services | D18: 46154 | E18: Cleaning/Supplies | F18: 280 | G18: 0.2 | H18: =F18*G18 -> 56 | I18: =F18*(1+G18) -> 336 | J18: Paid
A19: INV-FF-104 | B19: Camden | C19: Fresh Fields Wholesale Ltd | D19: 46177 | E19: Food | F19: 1377 | G19: 0 | H19: =F19*G19 -> 0 | I19: =F19*(1+G19) -> 1377 | J19: Paid | K19: Vendor rebranded from 'Fresh Fields Produce Ltd' this month — same supplier, new company name
A20: INV-CS-204 | B20: Camden | C20: Coastal Seafood Direct | D20: 46179 | E20: Food | F20: 1767.5 | G20: 0 | H20: =F20*G20 -> 0 | I20: =F20*(1+G20) -> 1767.5 | J20: Paid
A21: INV-MD-304 | B21: Camden | C21: Metro Drinks Wholesale | D21: 46183 | E21: Beverage | F21: 900 | G21: 0 | H21: =F21*G21 -> 0 | I21: =F21*(1+G21) -> 900 | J21: Paid | K21: VAT entered as 0% — alcohol should be standard-rated at 20%. Likely template copy-paste error from a food invoice.
A22: INV-GC-404 | B22: Camden | C22: Golden Crust Bakery Co | D22: 46181 | E22: Food | F22: 397.8 | G22: 0 | H22: =F22*G22 -> 0 | I22: =F22*(1+G22) -> 397.8 | J22: Paid
A23: INV-CP-504 | B23: Camden | C23: CleanPro Services | D23: 46185 | E23: Cleaning/Supplies | F23: 310 | G23: 0.2 | H23: =F23*G23 -> 62 | I23: =F23*(1+G23) -> 372 | J23: Paid
A24: INV-FF-105 | B24: Shoreditch | C24: Fresh Fields Wholesale Ltd | D24: 46177 | E24: Food | F24: 1285.2 | G24: 0 | H24: =F24*G24 -> 0 | I24: =F24*(1+G24) -> 1285.2 | J24: Paid | K24: Vendor rebranded from 'Fresh Fields Produce Ltd' this month — same supplier, new company name
A25: INV-CS-205 | B25: Shoreditch | C25: Coastal Seafood Direct | D25: 46179 | E25: Food | F25: 1610.95 | G25: 0 | H25: =F25*G25 -> 0 | I25: =F25*(1+G25) -> 1610.95 | J25: Paid
A26: INV-MD-305 | B26: Shoreditch | C26: Metro Drinks Wholesale | D26: 46183 | E26: Beverage | F26: 840 | G26: 0.2 | H26: =F26*G26 -> 168 | I26: =F26*(1+G26) -> 1008 | J26: Paid
A27: INV-GC-405 | B27: Shoreditch | C27: Golden Crust Bakery Co | D27: 46181 | E27: Food | F27: 367.2 | G27: 0 | H27: =F27*G27 -> 0 | I27: =F27*(1+G27) -> 367.2 | J27: Paid
A28: INV-CP-505 | B28: Shoreditch | C28: CleanPro Services | D28: 46185 | E28: Cleaning/Supplies | F28: 295 | G28: 0.2 | H28: =F28*G28 -> 59 | I28: =F28*(1+G28) -> 354 | J28: Paid
A29: INV-FF-106 | B29: Greenwich | C29: Fresh Fields Wholesale Ltd | D29: 46177 | E29: Food | F29: 1198.5 | G29: 0 | H29: =F29*G29 -> 0 | I29: =F29*(1+G29) -> 1198.5 | J29: Paid | K29: Vendor rebranded from 'Fresh Fields Produce Ltd' this month — same supplier, new company name
A30: INV-CS-206 | B30: Greenwich | C30: Coastal Seafood Direct | D30: 46179 | E30: Food | F30: 1565.5 | G30: 0 | H30: =F30*G30 -> 0 | I30: =F30*(1+G30) -> 1565.5 | J30: Paid
A31: INV-MD-306 | B31: Greenwich | C31: Metro Drinks Wholesale | D31: 46183 | E31: Beverage | F31: 760 | G31: 0.2 | H31: =F31*G31 -> 152 | I31: =F31*(1+G31) -> 912 | J31: Paid
A32: INV-GC-406 | B32: Greenwich | C32: Golden Crust Bakery Co | D32: 46181 | E32: Food | F32: 336.6 | G32: 0 | H32: =F32*G32 -> 0 | I32: =F32*(1+G32) -> 336.6 | J32: Paid
A33: INV-CP-506 | B33: Greenwich | C33: CleanPro Services | D33: 46185 | E33: Cleaning/Supplies | F33: 280 | G33: 0.2 | H33: =F33*G33 -> 56 | I33: =F33*(1+G33) -> 336 | J33: Paid
A34: INV-FF-107 | B34: Camden | C34: Fresh Fields Wholesale Ltd | D34: 46207 | E34: Food | F34: 1417.5 | G34: 0 | H34: =F34*G34 -> 0 | I34: =F34*(1+G34) -> 1417.5 | J34: Paid
A35: INV-CS-207 | B35: Camden | C35: Coastal Seafood Direct | D35: 46209 | E35: Food | F35: 2082.5 | G35: 0 | H35: =F35*G35 -> 0 | I35: =F35*(1+G35) -> 2082.5 | J35: Paid | K35: New unit pricing effective 1 Jul — see supplier price-increase letter
A36: INV-MD-307 | B36: Camden | C36: Metro Drinks Wholesale | D36: 46213 | E36: Beverage | F36: 927 | G36: 0.2 | H36: =F36*G36 -> 185.4 | I36: =F36*(1+G36) -> 1112.4 | J36: Paid
A37: INV-GC-407 | B37: Camden | C37: Golden Crust Bakery Co | D37: 46211 | E37: Food | F37: 401.7 | G37: 0 | H37: =F37*G37 -> 0 | I37: =F37*(1+G37) -> 401.7 | J37: Paid
A38: INV-CP-507 | B38: Camden | C38: CleanPro Services | D38: 46215 | E38: Cleaning/Supplies | F38: 310 | G38: 0.2 | H38: =F38*G38 -> 62 | I38: =F38*(1+G38) -> 372 | J38: Paid
A39: INV-CP-0714B | B39: Camden | C39: CleanPro Services | D39: 46215 | E39: Cleaning/Supplies | F39: 310 | G39: 0.2 | H39: =F39*G39 -> 62 | I39: =F39*(1+G39) -> 372 | J39: Paid | K39: Possible duplicate of INV-CP-507 — same date, same amount. Only ONE matching payment appears on the bank statement.
A40: INV-FF-108 | B40: Shoreditch | C40: Fresh Fields Wholesale Ltd | D40: 46207 | E40: Food | F40: 1323 | G40: 0 | H40: =F40*G40 -> 0 | I40: =F40*(1+G40) -> 1323 | J40: Paid
A41: INV-CS-208 | B41: Shoreditch | C41: Coastal Seafood Direct | D41: 46209 | E41: Food | F41: 1898.05 | G41: 0 | H41: =F41*G41 -> 0 | I41: =F41*(1+G41) -> 1898.05 | J41: Paid | K41: New unit pricing effective 1 Jul — see supplier price-increase letter
A42: INV-MD-308 | B42: Shoreditch | C42: Metro Drinks Wholesale | D42: 46213 | E42: Beverage | F42: 865.2 | G42: 0.2 | H42: =F42*G42 -> 173.04 | I42: =F42*(1+G42) -> 1038.24 | J42: Paid
A43: INV-GC-408 | B43: Shoreditch | C43: Golden Crust Bakery Co | D43: 46211 | E43: Food | F43: 370.8 | G43: 0 | H43: =F43*G43 -> 0 | I43: =F43*(1+G43) -> 370.8 | J43: Paid
...

Sheet Raw - Bank Statement
A1: Raw Data — Consolidated Bank Statement (May–Jul 2026, as downloaded)
A3: Date (parsed) | B3: Date (as entered) | C3: Site | D3: Description (as entered) | E3: Amount (£) | F3: Category (as entered) | G3: Matched Invoice ID | H3: Notes
A4: 46143 | B4: 01/05/2026 | C4: Camden | D4: DD - Landlord Rent May 2026 | E4: -3200 | F4: Rent
A5: 46143 | B5: 01/05/2026 | C5: Shoreditch | D5: DD - Landlord Rent May 2026 | E5: -2900 | F5: Rent
A6: 46143 | B6: 01/05/2026 | C6: Greenwich | D6: DD - Landlord Rent May 2026 | E6: -2700 | F6: Rent
A7: 46145 | B7: 03/05/2026 | C7: Camden | D7: DD - London Gas & Power | E7: -640 | F7: Utilities
A8: 46145 | B8: 03/05/2026 | C8: Shoreditch | D8: DD - London Gas & Power | E8: -520 | F8: Utilities
A9: 46145 | B9: 03/05/2026 | C9: Greenwich | D9: DD - London Gas & Power | E9: -580 | F9: Utilities
A10: 46152 | B10: 10/05/2026 | C10: Camden | D10: PAYMENT - Fresh Fields Produce Ltd | E10: -1350 | F10: Supplier Payment | G10: INV-FF-101
A11: 46152 | B11: 10/05/2026 | C11: Shoreditch | D11: PAYMENT - Fresh Fields Produce Ltd | E11: -1260 | F11: Supplier Payment | G11: INV-FF-102
A12: 46152 | B12: 10/05/2026 | C12: Greenwich | D12: PAYMENT - Fresh Fields Produce Ltd | E12: -1175 | F12: Supplier Payment | G12: INV-FF-103
A13: 46154 | B13: 12/05/2026 | C13: Camden | D13: PAYMENT - Coastal Seafood Direct | E13: -1750 | F13: Supplier Payment | G13: INV-CS-201
A14: 46154 | B14: 12/05/2026 | C14: Shoreditch | D14: PAYMENT - Coastal Seafood Direct | E14: -1595 | F14: Supplier Payment | G14: INV-CS-202
A15: 46154 | B15: 12/05/2026 | C15: Greenwich | D15: PAYMENT - Coastal Seafood Direct | E15: -1550 | F15: Supplier Payment | G15: INV-CS-203
A16: 46156 | B16: 14/05/2026 | C16: Camden | D16: PAYMENT - Golden Crust Bakery Co | E16: -390 | F16: Supplier Payment | G16: INV-GC-401
A17: 46156 | B17: 14/05/2026 | C17: Shoreditch | D17: PAYMENT - Golden Crust Bakery Co | E17: -360 | F17: Supplier Payment | G17: INV-GC-402
A18: 46156 | B18: 14/05/2026 | C18: Greenwich | D18: PAYMENT - Golden Crust Bakery Co | E18: -330 | F18: Supplier Payment | G18: INV-GC-403
A19: 46158 | B19: 16/05/2026 | C19: Camden | D19: PAYMENT - Metro Drinks Wholesale | E19: -1080 | F19: Supplier Payment | G19: INV-MD-301
A20: 46158 | B20: 16/05/2026 | C20: Shoreditch | D20: PAYMENT - Metro Drinks Wholesale | E20: -1008 | F20: Supplier Payment | G20: INV-MD-302
A21: 46158 | B21: 16/05/2026 | C21: Greenwich | D21: PAYMENT - Metro Drinks Wholesale | E21: -912 | F21: Supplier Payment | G21: INV-MD-303
... A28: 46168 | B28: 26/05/2026 | C28: Greenwich | D28: PAYMENT - Pest Control Solutions | E28: -174 | F28: Supplier Payment | G28: INV-PC-703
A29: 46169 | B29: 27/05/2026 | C29: Camden | D29: Deliveroo Payout (net of commission) | E29: 6480 | F29: Delivery Platform Payout
A30: 46169 | B30: 27/05/2026 | C30: Camden | D30: UberEats Payout (net of commission) | E30: 3850 | F30: Delivery Platform Payout
A31: 46169 | B31: 27/05/2026 | C31: Camden | D31: JustEat Payout (net of commission) | E31: 2580 | F31: Delivery Platform Payout
A32: 46169 | B32: 27/05/2026 | C32: Shoreditch | D32: Deliveroo Payout (net of commission) | E32: 7920 | F32: Delivery Platform Payout
A33: 46169 | B33: 27/05/2026 | C33: Shoreditch | D33: UberEats Payout (net of commission) | E33: 5600 | F33: Delivery Platform Payout
A34: 46169 | B34: 27/05/2026 | C34: Shoreditch | D34: JustEat Payout (net of commission) | E34: 2150 | F34: Delivery Platform Payout
A35: 46169 | B35: 27/05/2026 | C35: Greenwich | D35: Deliveroo Payout (net of commission) | E35: 2880 | F35: Delivery Platform Payout
A36: 46169 | B36: 27/05/2026 | C36: Greenwich | D36: UberEats Payout (net of commission) | E36: 2100 | F36: Delivery Platform Payout
A37: 46169 | B37: 27/05/2026 | C37: Greenwich | D37: JustEat Payout (net of commission) | E37: 1720 | F37: Delivery Platform Payout
A38: 46170 | B38: 28/05/2026 | C38: Camden | D38: Payroll BACS Transfer | E38: -17800 | F38: Payroll
A39: 46170 | B39: 28/05/2026 | C39: Shoreditch | D39: Payroll BACS Transfer | E39: -14600 | F39: Payroll
A40: 46170 | B40: 28/05/2026 | C40: Greenwich | D40: Payroll BACS Transfer | E40: -15400 | F40: Payroll
... A46: 46176 | B46: 03/06/2026 | C46: Greenwich | D46: DD - London Gas & Power | E46: -614.8 | F46: Utilities
A47: 46183 | B47: 10/06/2026 | C47: Camden | D47: PAYMENT - Fresh Fields Wholesale Ltd | E47: -1377 | F47: Supplier Payment | G47: INV-FF-104
A48: 46183 | B48: 10/06/2026 | C48: Shoreditch | D48: PAYMENT - Fresh Fields Wholesale Ltd | E48: -1285.2 | F48: Supplier Payment | G48: INV-FF-105
A49: 46183 | B49: 10/06/2026 | C49: Greenwich | D49: PAYMENT - Fresh Fields Wholesale Ltd | E49: -1198.5 | F49: Supplier Payment | G49: INV-FF-106
A50: 46185 | B50: 12/06/2026 | C50: Camden | D50: PAYMENT - Coastal Seafood Direct | E50: -1767.5 | F50: Supplier Payment | G50: INV-CS-204
A51: 46185 | B51: 12/06/2026 | C51: Shoreditch | D51: PAYMENT - Coastal Seafood Direct | E51: -1610.95 | F51: Supplier Payment | G51: INV-CS-205
A52: 46185 | B52: 12/06/2026 | C52: Greenwich | D52: PAYMENT - Coastal Seafood Direct | E52: -1565.5 | F52: Supplier Payment | G52: INV-CS-206
...

Sheet Raw - POS Sales Report
A1: Raw Data — POS Sales Report, consolidated monthly by site (May–Jul 2026)
A3: Month | B3: Site | C3: Dine-In (£) | D3: Takeaway (£) | E3: Delivery - Deliveroo Gross (£) | F3: Delivery - UberEats Gross (£) | G3: Delivery - JustEat Gross (£) | H3: Events/Catering (£) | I3: Total Sales (£)
A4: May 2026 | B4: Camden | C4: 28000 | D4: 6500 | E4: 9000 | F4: 5500 | G4: 3000 | H4: 4000 | I4: =SUM(C4:H4) -> 56000
A5: May 2026 | B5: Shoreditch | C5: 19000 | D5: 4000 | E5: 11000 | F5: 8000 | G5: 2500 | H5: 1500 | I5: =SUM(C5:H5) -> 46000
A6: May 2026 | B6: Greenwich | C6: 22000 | D6: 3000 | E6: 4000 | F6: 3000 | G6: 2000 | H6: 7000 | I6: =SUM(C6:H6) -> 41000
A7: Jun 2026 | B7: Camden | C7: 28840 | D7: 6695 | E7: 9270 | F7: 5665 | G7: 3090 | H7: 4000 | I7: =SUM(C7:H7) -> 57560
A8: Jun 2026 | B8: Shoreditch | C8: 19760 | D8: 4160 | E8: 11330 | F8: 8240 | G8: 2575 | H8: 1500 | I8: =SUM(C8:H8) -> 47565
A9: Jun 2026 | B9: Greenwich | C9: 22440 | D9: 3060 | E9: 4120 | F9: 3090 | G9: 2060 | H9: 7350 | I9: =SUM(C9:H9) -> 42120
A10: Jul 2026 | B10: Camden | C10: 30800 | D10: 7150 | E10: 9900 | F10: 6050 | G10: 3300 | H10: 4200 | I10: =SUM(C10:H10) -> 61400
A11: Jul 2026 | B11: Shoreditch | C11: 21280 | D11: 4480 | E11: 12320 | F11: 8960 | G11: 2800 | H11: 1500 | I11: =SUM(C11:H11) -> 51340
A12: Jul 2026 | B12: Greenwich | C12: 23320 | D12: 3180 | E12: 4240 | F12: 3180 | G12: 2120 | H12: 8400 | I12: =SUM(C12:H12) -> 44440

Sheet Raw - Payroll Summary
A1: Raw Data — Payroll Summary by site (May–Jul 2026)
A3: Month | B3: Site | C3: Basic Wages (£) | D3: Overtime (£) | E3: Tronc/Tips Distributed (£) | F3: Employer NI (£) | G3: Pension Contribution (£) | H3: Total Payroll Outgoing (£)
A4: May 2026 | B4: Camden | C4: 14000 | D4: 900 | E4: 2200 | F4: 1450 | G4: 420 | H4: =SUM(C4:G4) -> 18970
A5: May 2026 | B5: Shoreditch | C5: 11500 | D5: 750 | E5: 2600 | F5: 1180 | G5: 345 | H5: =SUM(C5:G5) -> 16375
A6: May 2026 | B6: Greenwich | C6: 12800 | D6: 680 | E6: 1900 | F6: 1310 | G6: 385 | H6: =SUM(C6:G6) -> 17075
A7: Jun 2026 | B7: Camden | C7: 14000 | D7: 945 | E7: 2200 | F7: 1450 | G7: 420 | H7: =SUM(C7:G7) -> 19015
A8: Jun 2026 | B8: Shoreditch | C8: 11500 | D8: 787.5 | E8: 2600 | F8: 1180 | G8: 345 | H8: =SUM(C8:G8) -> 16412.5
A9: Jun 2026 | B9: Greenwich | C9: 12800 | D9: 714 | E9: 1900 | F9: 1310 | G9: 385 | H9: =SUM(C9:G9) -> 17109
A10: Jul 2026 | B10: Camden | C10: 14000 | D10: 1170 | E10: 2200 | F10: 1450 | G10: 420 | H10: =SUM(C10:G10) -> 19240
A11: Jul 2026 | B11: Shoreditch | C11: 11500 | D11: 975 | E11: 2600 | F11: 1180 | G11: 345 | H11: =SUM(C11:G11) -> 16600
A12: Jul 2026 | B12: Greenwich | C12: 12800 | D12: 884 | E12: 1900 | F12: 1310 | G12: 385 | H12: =SUM(C12:G12) -> 17279
A14: Note: Tronc/Tips are fully redistributed to staff and are excluded from Payroll Cost in the P&L — they are a pass-through, not a real cost to the business.

Sheet Monthly P&L (Demo - Start Here)
A1: Three Sisters Kitchen — Monthly Report
A3: Line Item | B3: May 2026 | C3: Jun 2026 | D3: Jul 2026
A4: Revenue
A5: Dine-In
A6: Takeaway
A7: Delivery Revenue (net of commission)
A8: Events / Catering
A9: Total Revenue
A10: Cost of Goods Sold (COGS)
A11: Food Cost
A12: Beverage Cost
A13: Total COGS
A14: Gross Profit
A15: Gross Profit
... A23: EBITDA

Sheet Monthly P&L (Answer Key)
A1: Three Sisters Kitchen — Monthly P&L (Answer Key, consolidated across all 3 sites)
A2: Built entirely with formulas from the four Raw Data sheets — nothing hardcoded except the commission-rate assumptions below.
A4: Assumptions — Delivery Platform Commission Rates
A5: Platform | B5: May 2026 | C5: Jun 2026 | D5: Jul 2026
A6: Deliveroo | B6: 0.28 | C6: 0.3 | D6: 0.3
A7: UberEats | B7: 0.3 | C7: 0.3 | D7: 0.3
A8: JustEat | B8: 0.14 | C8: 0.14 | D8: 0.14
A9: Note: Deliveroo commission rose from 28% to 30% starting June — buried inside the net payout figure on the bank statement.
A12: Line Item | B12: May 2026 | C12: Jun 2026 | D12: Jul 2026
A13: Revenue
A14: Dine-In | B14: =SUMIF('Raw - POS Sales Report'!$A:$A,"May 2026",'Raw - POS Sales Report'!$C:$C) -> 69000 | C14: =SUMIF('Raw - POS Sales Report'!$A:$A,"Jun 2026",'Raw - POS Sales Report'!$C:$C) -> 71040 | D14: =SUMIF('Raw - POS Sales Report'!$A:$A,"Jul 2026",'Raw - POS Sales Report'!$C:$C) -> 75400
A15: Takeaway | B15: =SUMIF('Raw - POS Sales Report'!$A:$A,"May 2026",'Raw - POS Sales Report'!$D:$D) -> 13500 | C15: =SUMIF('Raw - POS Sales Report'!$A:$A,"Jun 2026",'Raw - POS Sales Report'!$D:$D) -> 13915 | D15: =SUMIF('Raw - POS Sales Report'!$A:$A,"Jul 2026",'Raw - POS Sales Report'!$D:$D) -> 14810
A16: Delivery Revenue (net of commission) | B16: =SUMIF('Raw - POS Sales Report'!$A:$A,"May 2026",'Raw - POS Sales Report'!$E:$E)*(1-B6)+SUMIF('Raw - POS Sales Report'!$A:$A,"May 2026",'Raw - POS Sales Report'!$F:$F)*(1-B7)+SUMIF('Raw - POS Sales Report'!$A:$A,"May 2026",'Raw - POS Sales Report'!$G:$G)*(1-B8) -> 35280 | C16: =SUMIF('Raw - POS Sales Report'!$A:$A,"Jun 2026",'Raw - POS Sales Report'!$E:$E)*(1-C6)+SUMIF('Raw - POS Sales Report'!$A:$A,"Jun 2026",'Raw - POS Sales Report'!$F:$F)*(1-C7)+SUMIF('Raw - POS Sales Report'!$A:$A,"Jun 2026",'Raw - POS Sales Report'!$G:$G)*(1-C8) -> 35844 | D16: =SUMIF('Raw - POS Sales Report'!$A:$A,"Jul 2026",'Raw - POS Sales Report'!$E:$E)*(1-D6)+SUMIF('Raw - POS Sales Report'!$A:$A,"Jul 2026",'Raw - POS Sales Report'!$F:$F)*(1-D7)+SUMIF('Raw - POS Sales Report'!$A:$A,"Jul 2026",'Raw - POS Sales Report'!$G:$G)*(1-D8) -> 38324.2
A17: Events / Catering | B17: =SUMIF('Raw - POS Sales Report'!$A:$A,"May 2026",'Raw - POS Sales Report'!$H:$H) -> 12500 | C17: =SUMIF('Raw - POS Sales Report'!$A:$A,"Jun 2026",'Raw - POS Sales Report'!$H:$H) -> 12850 | D17: =SUMIF('Raw - POS Sales Report'!$A:$A,"Jul 2026",'Raw - POS Sales Report'!$H:$H) -> 14100
A18: Total Revenue | B18: =SUM(B14:B17) -> 130280 | C18: =SUM(C14:C17) -> 133649 | D18: =SUM(D14:D17) -> 142634.2
A19: Cost of Goods Sold (COGS)
A20: Food Cost | B20: =SUMIFS('Raw - Supplier Invoices'!$F:$F,'Raw - Supplier Invoices'!$E:$E,"Food",'Raw - Supplier Invoices'!$D:$D,">="&DATE(2026,5,1),'Raw - Supplier Invoices'!$D:$D,"<="&DATE(2026,5,31)) -> 9760 | C20: =SUMIFS('Raw - Supplier Invoices'!$F:$F,'Raw - Supplier Invoices'!$E:$E,"Food",'Raw - Supplier Invoices'!$D:$D,">="&DATE(2026,6,1),'Raw - Supplier Invoices'!$D:$D,"<="&DATE(2026,6,30)) -> 9906.25 | D20: =SUMIFS('Raw - Supplier Invoices'!$F:$F,'Raw - Supplier Invoices'!$E:$E,"Food",'Raw - Supplier Invoices'!$D:$D,">="&DATE(2026,7,1),'Raw - Supplier Invoices'!$D:$D,"<="&DATE(2026,7,31)) -> 10911.7
A21: Beverage Cost | B21: =SUMIFS('Raw - Supplier Invoices'!$F:$F,'Raw - Supplier Invoices'!$E:$E,"Beverage",'Raw - Supplier Invoices'!$D:$D,">="&DATE(2026,5,1),'Raw - Supplier Invoices'!$D:$D,"<="&DATE(2026,5,31)) -> 2500 | C21: =SUMIFS('Raw - Supplier Invoices'!$F:$F,'Raw - Supplier Invoices'!$E:$E,"Beverage",'Raw - Supplier Invoices'!$D:$D,">="&DATE(2026,6,1),'Raw - Supplier Invoices'!$D:$D,"<="&DATE(2026,6,30)) -> 2500 | D21: =SUMIFS('Raw - Supplier Invoices'!$F:$F,'Raw - Supplier Invoices'!$E:$E,"Beverage",'Raw - Supplier Invoices'!$D:$D,">="&DATE(2026,7,1),'Raw - Supplier Invoices'!$D:$D,"<="&DATE(2026,7,31)) -> 2575
A22: Total COGS | B22: =SUM(B20:B21) -> 12260 | C22: =SUM(C20:C21) -> 12406.25 | D22: =SUM(D20:D21) -> 13486.7
A23: Gross Profit
A24: Gross Profit | B24: =B18-B22 -> 118020 | C24: =C18-C22 -> 121242.75 | D24: =D18-D22 -> 129147.5
A25: Operating Expenses
A26: Payroll Cost (excl. Tronc) | B26: =SUMIF('Raw - Payroll Summary'!$A:$A,"May 2026",'Raw - Payroll Summary'!$C:$C)+SUMIF('Raw - Payroll Summary'!$A:$A,"May 2026",'Raw - Payroll Summary'!$D:$D)+SUMIF('Raw - Payroll Summary'!$A:$A,"May 2026",'Raw - Payroll Summary'!$F:$F)+SUMIF('Raw - Payroll Summary'!$A:$A,"May 2026",'Raw - Payroll Summary'!$G:$G) -> 45720 | C26: =SUMIF('Raw - Payroll Summary'!$A:$A,"Jun 2026",'Raw - Payroll Summary'!$C:$C)+SUMIF('Raw - Payroll Summary'!$A:$A,"Jun 2026",'Raw - Payroll Summary'!$D:$D)+SUMIF('Raw - Payroll Summary'!$A:$A,"Jun 2026",'Raw - Payroll Summary'!$F:$F)+SUMIF('Raw - Payroll Summary'!$A:$A,"Jun 2026",'Raw - Payroll Summary'!$G:$G) -> 45836.5 | D26: =SUMIF('Raw - Payroll Summary'!$A:$A,"Jul 2026",'Raw - Payroll Summary'!$C:$C)+SUMIF('Raw - Payroll Summary'!$A:$A,"Jul 2026",'Raw - Payroll Summary'!$D:$D)+SUMIF('Raw - Payroll Summary'!$A:$A,"Jul 2026",'Raw - Payroll Summary'!$F:$F)+SUMIF('Raw - Payroll Summary'!$A:$A,"Jul 2026",'Raw - Payroll Summary'!$G:$G) -> 46419
A27: Rent | B27: =SUMIFS('Raw - Bank Statement'!$E:$E,'Raw - Bank Statement'!$F:$F,"Rent",'Raw - Bank Statement'!$A:$A,">="&DATE(2026,5,1),'Raw - Bank Statement'!$A:$A,"<="&DATE(2026,5,31))*-1 -> 8800 | C27: =SUMIFS('Raw - Bank Statement'!$E:$E,'Raw - Bank Statement'!$F:$F,"Rent",'Raw - Bank Statement'!$A:$A,">="&DATE(2026,6,1),'Raw - Bank Statement'!$A:$A,"<="&DATE(2026,6,30))*-1 -> 8800 | D27: =SUMIFS('Raw - Bank Statement'!$E:$E,'Raw - Bank Statement'!$F:$F,"Rent",'Raw - Bank Statement'!$A:$A,">="&DATE(2026,7,1),'Raw - Bank Statement'!$A:$A,"<="&DATE(2026,7,31))*-1 -> 8800
A28: Utilities | B28: =SUMIFS('Raw - Bank Statement'!$E:$E,'Raw - Bank Statement'!$F:$F,"Utilities",'Raw - Bank Statement'!$A:$A,">="&DATE(2026,5,1),'Raw - Bank Statement'!$A:$A,"<="&DATE(2026,5,31))*-1 -> 1740 | C28: =SUMIFS('Raw - Bank Statement'!$E:$E,'Raw - Bank Statement'!$F:$F,"Utilities",'Raw - Bank Statement'!$A:$A,">="&DATE(2026,6,1),'Raw - Bank Statement'!$A:$A,"<="&DATE(2026,6,30))*-1 -> 1844.4 | D28: =SUMIFS('Raw - Bank Statement'!$E:$E,'Raw - Bank Statement'!$F:$F,"Utilities",'Raw - Bank Statement'!$A:$A,">="&DATE(2026,7,1),'Raw - Bank Statement'!$A:$A,"<="&DATE(2026,7,31))*-1 -> 2122.8
A29: Other Opex (Cleaning, Maintenance, Marketing) | B29: =SUMIFS('Raw - Supplier Invoices'!$F:$F,'Raw - Supplier Invoices'!$E:$E,"Cleaning/Supplies",'Raw - Supplier Invoices'!$D:$D,">="&DATE(2026,5,1),'Raw - Supplier Invoices'!$D:$D,"<="&DATE(2026,5,31))+SUMIFS('Raw - Supplier Invoices'!$F:$F,'Raw - Supplier Invoices'!$E:$E,"Maintenance",'Raw - Supplier Invoices'!$D:$D,">="&DATE(2026,5,1),'Raw - Supplier Invoices'!$D:$D,"<="&DATE(2026,5,31))+SUMIFS('Raw - Supplier Invoices'!$F:$F,'Raw - Supplier Invoices'!$E:$E,"Marketing",'Raw - Supplier Invoices'!$D:$D,">="&DATE(2026,5,1),'Raw - Supplier Invoices'!$D:$D,"<="&DATE(2026,5,31)) -> 1715 | C29: =SUMIFS('Raw - Supplier Invoices'!$F:$F,'Raw - Supplier Invoices'!$E:$E,"Cleaning/Supplies",'Raw - Supplier Invoices'!$D:$D,">="&DATE(2026,6,1),'Raw - Supplier Invoices'!$D:$D,"<="&DATE(2026,6,30))+SUMIFS('Raw - Supplier Invoices'!$F:$F,'Raw - Supplier Invoices'!$E:$E,"Maintenance",'Raw - Supplier Invoices'!$D:$D,">="&DATE(2026,6,1),'Raw - Supplier Invoices'!$D:$D,"<="&DATE(2026,6,30))+SUMIFS('Raw - Supplier Invoices'!$F:$F,'Raw - Supplier Invoices'!$E:$E,"Marketing",'Raw - Supplier Invoices'!$D:$D,">="&DATE(2026,6,1),'Raw - Supplier Invoices'!$D:$D,"<="&DATE(2026,6,30)) -> 1485 | D29: =SUMIFS('Raw - Supplier Invoices'!$F:$F,'Raw - Supplier Invoices'!$E:$E,"Cleaning/Supplies",'Raw - Supplier Invoices'!$D:$D,">="&DATE(2026,7,1),'Raw - Supplier Invoices'!$D:$D,"<="&DATE(2026,7,31))+SUMIFS('Raw - Supplier Invoices'!$F:$F,'Raw - Supplier Invoices'!$E:$E,"Maintenance",'Raw - Supplier Invoices'!$D:$D,">="&DATE(2026,7,1),'Raw - Supplier Invoices'!$D:$D,"<="&DATE(2026,7,31))+SUMIFS('Raw - Supplier Invoices'!$F:$F,'Raw - Supplier Invoices'!$E:$E,"Marketing",'Raw - Supplier Invoices'!$D:$D,">="&DATE(2026,7,1),'Raw - Supplier Invoices'!$D:$D,"<="&DATE(2026,7,31)) -> 1605
A30: Total Operating Expenses | B30: =SUM(B26:B29) -> 57975 | C30: =SUM(C26:C29) -> 57965.9 | D30: =SUM(D26:D29) -> 58946.8
A31: EBITDA
A32: EBITDA | B32: =B24-B30 -> 60045 | C32: =C24-C30 -> 63276.85 | D32: =D24-D30 -> 70200.7

Sheet Variance Analysis
A1: Variance Analysis — Month over Month (references Monthly P&L Answer Key)
A2: Flag = TRUE where the movement is >10% — a reasonable first-pass threshold for what deserves a look, not a hard rule.
A4: Line Item | B4: Jun vs May (£) | C4: Jun vs May (%) | D4: Jul vs Jun (£) | E4: Jul vs Jun (%) | F4: Flag (>10%) | G4: Explanation
A5: Total Revenue | B5: ='Monthly P&L (Answer Key)'!C18-'Monthly P&L (Answer Key)'!B18 -> 3369 | C5: =IFERROR(('Monthly P&L (Answer Key)'!C18-'Monthly P&L (Answer Key)'!B18)/'Monthly P&L (Answer Key)'!B18,0) -> 0.025859687 | D5: ='Monthly P&L (Answer Key)'!D18-'Monthly P&L (Answer Key)'!C18 -> 8985.2 | E5: =IFERROR(('Monthly P&L (Answer Key)'!D18-'Monthly P&L (Answer Key)'!C18)/'Monthly P&L (Answer Key)'!C18,0) -> 0.067229833 | F5: =IF(OR(ABS(C5)>0.1,ABS(E5)>0.1),TRUE(),FALSE()) -> FALSE
A6: Dine-In | B6: ='Monthly P&L (Answer Key)'!C14-'Monthly P&L (Answer Key)'!B14 -> 2040 | C6: =IFERROR(('Monthly P&L (Answer Key)'!C14-'Monthly P&L (Answer Key)'!B14)/'Monthly P&L (Answer Key)'!B14,0) -> 0.029565217 | D6: ='Monthly P&L (Answer Key)'!D14-'Monthly P&L (Answer Key)'!C14 -> 4360 | E6: =IFERROR(('Monthly P&L (Answer Key)'!D14-'Monthly P&L (Answer Key)'!C14)/'Monthly P&L (Answer Key)'!C14,0) -> 0.061373874 | F6: =IF(OR(ABS(C6)>0.1,ABS(E6)>0.1),TRUE(),FALSE()) -> FALSE
A7: Takeaway | B7: ='Monthly P&L (Answer Key)'!C15-'Monthly P&L (Answer Key)'!B15 -> 415 | C7: =IFERROR(('Monthly P&L (Answer Key)'!C15-'Monthly P&L (Answer Key)'!B15)/'Monthly P&L (Answer Key)'!B15,0) -> 0.030740741 | D7: ='Monthly P&L (Answer Key)'!D15-'Monthly P&L (Answer Key)'!C15 -> 895 | E7: =IFERROR(('Monthly P&L (Answer Key)'!D15-'Monthly P&L (Answer Key)'!C15)/'Monthly P&L (Answer Key)'!C15,0) -> 0.06431908 | F7: =IF(OR(ABS(C7)>0.1,ABS(E7)>0.1),TRUE(),FALSE()) -> FALSE
A8: Delivery Revenue (net of commission) | B8: ='Monthly P&L (Answer Key)'!C16-'Monthly P&L (Answer Key)'!B16 -> 564 | C8: =IFERROR(('Monthly P&L (Answer Key)'!C16-'Monthly P&L (Answer Key)'!B16)/'Monthly P&L (Answer Key)'!B16,0) -> 0.015986395 | D8: ='Monthly P&L (Answer Key)'!D16-'Monthly P&L (Answer Key)'!C16 -> 2480.2 | E8: =IFERROR(('Monthly P&L (Answer Key)'!D16-'Monthly P&L (Answer Key)'!C16)/'Monthly P&L (Answer Key)'!C16,0) -> 0.069194286 | F8: =IF(OR(ABS(C8)>0.1,ABS(E8)>0.1),TRUE(),FALSE()) -> FALSE | G8: Deliveroo commission rose from 28% to 30% from June — net delivery revenue understates gross platform sales growth. Check gross Deliveroo sales in the POS sheet before concluding delivery demand fell.
A9: Events / Catering | B9: ='Monthly P&L (Answer Key)'!C17-'Monthly P&L (Answer Key)'!B17 -> 350 | C9: =IFERROR(('Monthly P&L (Answer Key)'!C17-'Monthly P&L (Answer Key)'!B17)/'Monthly P&L (Answer Key)'!B17,0) -> 0.028 | D9: ='Monthly P&L (Answer Key)'!D17-'Monthly P&L (Answer Key)'!C17 -> 1250 | E9: =IFERROR(('Monthly P&L (Answer Key)'!D17-'Monthly P&L (Answer Key)'!C17)/'Monthly P&L (Answer Key)'!C17,0) -> 0.097276265 | F9: =IF(OR(ABS(C9)>0.1,ABS(E9)>0.1),TRUE(),FALSE()) -> FALSE
A10: Food Cost | B10: ='Monthly P&L (Answer Key)'!C20-'Monthly P&L (Answer Key)'!B20 -> 146.25 | C10: =IFERROR(('Monthly P&L (Answer Key)'!C20-'Monthly P&L (Answer Key)'!B20)/'Monthly P&L (Answer Key)'!B20,0) -> 0.014984631 | D10: ='Monthly P&L (Answer Key)'!D20-'Monthly P&L (Answer Key)'!C20 -> 1005.45 | E10: =IFERROR(('Monthly P&L (Answer Key)'!D20-'Monthly P&L (Answer Key)'!C20)/'Monthly P&L (Answer Key)'!C20,0) -> 0.10149653 | F10: =IF(OR(ABS(C10)>0.1,ABS(E10)>0.1),TRUE(),FALSE()) -> TRUE | G10: Jul rise reflects a confirmed ~18% Coastal Seafood price increase (see supplier letter, Raw - Supplier Invoices) — but a July heatwave may also have driven wastage. Both are plausible; not resolved here on purpose. Confirm with site managers before booking as a pure supplier-price effect.
A11: Beverage Cost | B11: ='Monthly P&L (Answer Key)'!C21-'Monthly P&L (Answer Key)'!B21 -> 0 | C11: =IFERROR(('Monthly P&L (Answer Key)'!C21-'Monthly P&L (Answer Key)'!B21)/'Monthly P&L (Answer Key)'!B21,0) -> 0 | D11: ='Monthly P&L (Answer Key)'!D21-'Monthly P&L (Answer Key)'!C21 -> 75 | E11: =IFERROR(('Monthly P&L (Answer Key)'!D21-'Monthly P&L (Answer Key)'!C21)/'Monthly P&L (Answer Key)'!C21,0) -> 0.03 | F11: =IF(OR(ABS(C11)>0.1,ABS(E11)>0.1),TRUE(),FALSE()) -> FALSE | G11: Camden's June Metro Drinks invoice had VAT misapplied at 0% instead of 20% — net cost line is unaffected, but the VAT return for that period will be wrong until corrected.
A12: Total COGS | B12: ='Monthly P&L (Answer Key)'!C22-'Monthly P&L (Answer Key)'!B22 -> 146.25 | C12: =IFERROR(('Monthly P&L (Answer Key)'!C22-'Monthly P&L (Answer Key)'!B22)/'Monthly P&L (Answer Key)'!B22,0) -> 0.011929038 | D12: ='Monthly P&L (Answer Key)'!D22-'Monthly P&L (Answer Key)'!C22 -> 1080.45 | E12: =IFERROR(('Monthly P&L (Answer Key)'!D22-'Monthly P&L (Answer Key)'!C22)/'Monthly P&L (Answer Key)'!C22,0) -> 0.087089169 | F12: =IF(OR(ABS(C12)>0.1,ABS(E12)>0.1),TRUE(),FALSE()) -> FALSE
A13: Gross Profit | B13: ='Monthly P&L (Answer Key)'!C24-'Monthly P&L (Answer Key)'!B24 -> 3222.75 | C13: =IFERROR(('Monthly P&L (Answer Key)'!C24-'Monthly P&L (Answer Key)'!B24)/'Monthly P&L (Answer Key)'!B24,0) -> 0.027306812 | D13: ='Monthly P&L (Answer Key)'!D24-'Monthly P&L (Answer Key)'!C24 -> 7904.75 | E13: =IFERROR(('Monthly P&L (Answer Key)'!D24-'Monthly P&L (Answer Key)'!C24)/'Monthly P&L (Answer Key)'!C24,0) -> 0.065197713 | F13: =IF(OR(ABS(C13)>0.1,ABS(E13)>0.1),TRUE(),FALSE()) -> FALSE
A14: Payroll Cost (excl. Tronc) | B14: ='Monthly P&L (Answer Key)'!C26-'Monthly P&L (Answer Key)'!B26 -> 116.5 | C14: =IFERROR(('Monthly P&L (Answer Key)'!C26-'Monthly P&L (Answer Key)'!B26)/'Monthly P&L (Answer Key)'!B26,0) -> 0.002548119 | D14: ='Monthly P&L (Answer Key)'!D26-'Monthly P&L (Answer Key)'!C26 -> 582.5 | E14: =IFERROR(('Monthly P&L (Answer Key)'!D26-'Monthly P&L (Answer Key)'!C26)/'Monthly P&L (Answer Key)'!C26,0) -> 0.012708213 | F14: =IF(OR(ABS(C14)>0.1,ABS(E14)>0.1),TRUE(),FALSE()) -> FALSE | G14: July overtime rises ~30% across all sites — consistent with summer trading volume, not a one-off anomaly.
A15: Rent | B15: ='Monthly P&L (Answer Key)'!C27-'Monthly P&L (Answer Key)'!B27 -> 0 | C15: =IFERROR(('Monthly P&L (Answer Key)'!C27-'Monthly P&L (Answer Key)'!B27)/'Monthly P&L (Answer Key)'!B27,0) -> 0 | D15: ='Monthly P&L (Answer Key)'!D27-'Monthly P&L (Answer Key)'!C27 -> 0 | E15: =IFERROR(('Monthly P&L (Answer Key)'!D27-'Monthly P&L (Answer Key)'!C27)/'Monthly P&L (Answer Key)'!C27,0) -> 0 | F15: =IF(OR(ABS(C15)>0.1,ABS(E15)>0.1),TRUE(),FALSE()) -> FALSE | G15: Flat by design — no change expected month to month.
A16: Utilities | B16: ='Monthly P&L (Answer Key)'!C28-'Monthly P&L (Answer Key)'!B28 -> 104.4 | C16: =IFERROR(('Monthly P&L (Answer Key)'!C28-'Monthly P&L (Answer Key)'!B28)/'Monthly P&L (Answer Key)'!B28,0) -> 0.06 | D16: ='Monthly P&L (Answer Key)'!D28-'Monthly P&L (Answer Key)'!C28 -> 278.4 | E16: =IFERROR(('Monthly P&L (Answer Key)'!D28-'Monthly P&L (Answer Key)'!C28)/'Monthly P&L (Answer Key)'!C28,0) -> 0.1509434 | F16: =IF(OR(ABS(C16)>0.1,ABS(E16)>0.1),TRUE(),FALSE()) -> TRUE | G16: July rise driven by air conditioning load during the summer heatwave — same heatwave referenced in the Food Cost note above.
A17: Other Opex (Cleaning, Maintenance, Marketing) | B17: ='Monthly P&L (Answer Key)'!C29-'Monthly P&L (Answer Key)'!B29 -> -230 | C17: =IFERROR(('Monthly P&L (Answer Key)'!C29-'Monthly P&L (Answer Key)'!B29)/'Monthly P&L (Answer Key)'!B29,0) -> -0.13411079 | D17: ='Monthly P&L (Answer Key)'!D29-'Monthly P&L (Answer Key)'!C29 -> 120 | E17: =IFERROR(('Monthly P&L (Answer Key)'!D29-'Monthly P&L (Answer Key)'!C29)/'Monthly P&L (Answer Key)'!C29,0) -> 0.080808081 | F17: =IF(OR(ABS(C17)>0.1,ABS(E17)>0.1),TRUE(),FALSE()) -> TRUE | G17: June includes a one-off £600 summer marketing campaign, billed centrally through Camden.
A18: Total Operating Expenses | B18: ='Monthly P&L (Answer Key)'!C30-'Monthly P&L (Answer Key)'!B30 -> -9.1 | C18: =IFERROR(('Monthly P&L (Answer Key)'!C30-'Monthly P&L (Answer Key)'!B30)/'Monthly P&L (Answer Key)'!B30,0) -> -0.00015696421 | D18: ='Monthly P&L (Answer Key)'!D30-'Monthly P&L (Answer Key)'!C30 -> 980.9 | E18: =IFERROR(('Monthly P&L (Answer Key)'!D30-'Monthly P&L (Answer Key)'!C30)/'Monthly P&L (Answer Key)'!C30,0) -> 0.016922018 | F18: =IF(OR(ABS(C18)>0.1,ABS(E18)>0.1),TRUE(),FALSE()) -> FALSE
A19: EBITDA | B19: ='Monthly P&L (Answer Key)'!C32-'Monthly P&L (Answer Key)'!B32 -> 3231.85 | C19: =IFERROR(('Monthly P&L (Answer Key)'!C32-'Monthly P&L (Answer Key)'!B32)/'Monthly P&L (Answer Key)'!B32,0) -> 0.053823799 | D19: ='Monthly P&L (Answer Key)'!D32-'Monthly P&L (Answer Key)'!C32 -> 6923.85 | E19: =IFERROR(('Monthly P&L (Answer Key)'!D32-'Monthly P&L (Answer Key)'!C32)/'Monthly P&L (Answer Key)'!C32,0) -> 0.10942153 | F19: =IF(OR(ABS(C19)>0.1,ABS(E19)>0.1),TRUE(),FALSE()) -> TRUE
